<?xml version="1.0" ?>
<!-- =================================================================================== -->
<!-- |    This document was autogenerated by xacro from sobit_pro.urdf.xacro           | -->
<!-- |    EDITING THIS FILE BY HAND IS NOT RECOMMENDED                                 | -->
<!-- =================================================================================== -->
<robot name="sobit_pro" xmlns:controller="http://playerstage.sourceforge.net/gazebo/xmlschema/#controller" xmlns:interface="http://playerstage.sourceforge.net/gazebo/xmlschema/#interface" xmlns:sensor="http://playerstage.sourceforge.net/gazebo/xmlschema/#sensor">
  <material name="wheel">
    <color rgba="0.2 0.2 0.2 1.0"/>
  </material>
  <material name="black">
    <color rgba="0.1 0.1 0.1 1.0"/>
  </material>
  <material name="red">
    <color rgba="1.0 0.0 0.0 1.0"/>
  </material>
  <material name="green">
    <color rgba="0.0 1.0 0.0 1.0"/>
  </material>
  <material name="blue">
    <color rgba="0.0 0.0 1.0 1.0"/>
  </material>
  <material name="white">
    <color rgba="1.0 1.0 1.0 1.0"/>
  </material>
  <material name="grey">
    <color rgba="0.3 0.3 0.3 1.0"/>
  </material>
  <material name="dark_grey">
    <color rgba="0.175 0.175 0.175 1.0"/>
  </material>
  <material name="brown">
    <color rgba="0.6 0.3 0.0 1.0"/>
  </material>
  <material name="aluminum">
    <color rgba="0.5 0.5 0.5 1"/>
  </material>
  <material name="plastic">
    <color rgba="0.1 0.1 0.1 1"/>
  </material>
  <!-- this specific plug does not apply to L515 -->
  <link name="base_footprint"/>


  <joint name="base_joint" type="fixed">
    <parent link="base_footprint"/>
    <child link="base_link"/>
    <origin rpy="0.0 0.0 0.0" xyz="0 0 0.177"/>
  </joint>
  <link name="base_link"/>
  &gt;

    
  <joint name="plate_bottom_joint" type="fixed">
    <origin rpy="0.0 0.0 0.0" xyz="0.0 0.0 0.0"/>
    <parent link="base_link"/>
    <child link="plate_bottom_link"/>
  </joint>
  <link name="plate_bottom_link">
    <visual>
      <origin rpy="0.0 0.0 0.0" xyz="0.0 0.0 0.0"/>
      <geometry>
        <mesh filename="/home/sobits/catkin_ws/src/sobit_pro/sobit_pro_description/meshes/body/plate_bottom.stl" scale="0.001 0.001 0.001"/>
      </geometry>
      <material name="black"/>
    </visual>
    <!-- <collision>
      <origin rpy="0.0 0.0 0.0" xyz="0.0 0.0 0.0"/>
      <geometry>
        <mesh filename="/home/sobits/catkin_ws/src/sobit_pro/sobit_pro_description/meshes/body/plate_bottom.stl" scale="0.001 0.001 0.001"/>
      </geometry>
    </collision> -->
    <inertial>
      <origin rpy="0.0 0.0 0.0" xyz="0.0 0.0 0.0"/>
      <mass value="75.0"/>
      <!-- <mass value="2.7779999999999996"/> -->
      <inertia ixx="1.0" ixy="0.0" ixz="0.0" iyy="1.0" iyz="0.0" izz="1.0"/>
    </inertial>
  </link>


  <joint name="plate_middle_joint" type="fixed">
    <origin rpy="0.0 0.0 0.0" xyz="0.0 0.0 0.064"/>
    <parent link="plate_bottom_link"/>
    <child link="plate_middle_link"/>
  </joint>
  <link name="plate_middle_link">
    <visual>
      <origin rpy="0.0 0.0 0.0" xyz="0.0 0.0 0.0"/>
      <geometry>
        <mesh filename="/home/sobits/catkin_ws/src/sobit_pro/sobit_pro_description/meshes/body/plate_middle.stl" scale="0.001 0.001 0.001"/>
      </geometry>
      <material name="black"/>
    </visual>
    <!-- <collision>
      <origin rpy="0.0 0.0 0.0" xyz="0.0 0.0 0.0"/>
      <geometry>
        <mesh filename="/home/sobits/catkin_ws/src/sobit_pro/sobit_pro_description/meshes/body/plate_middle.stl" scale="0.001 0.001 0.001"/>
      </geometry>
    </collision> -->
    <inertial>
      <origin rpy="0.0 0.0 0.0" xyz="0.0 0.0 0.0"/>
      <mass value="2.508"/>
      <inertia ixx="1.0" ixy="0.0" ixz="0.0" iyy="1.0" iyz="0.0" izz="1.0"/>
    </inertial>
  </link>


  <joint name="plate_top_joint" type="fixed">
    <origin rpy="0.0 0.0 0.0" xyz="0.0 0.0 0.4800"/>
    <parent link="plate_middle_link"/>
    <child link="plate_top_link"/>
  </joint>
  <link name="plate_top_link">
    <visual>
      <origin rpy="0.0 0.0 1.570796326795" xyz="0.0 0.0 0.0"/>
      <geometry>
        <mesh filename="/home/sobits/catkin_ws/src/sobit_pro/sobit_pro_description/meshes/body/plate_top.stl" scale="0.001 0.001 0.001"/>
      </geometry>
      <material name="black"/>
    </visual>
    <!-- <collision>
      <origin rpy="0.0 0.0 1.570796326795" xyz="0.0 0.0 0.0"/>
      <geometry>
        <mesh filename="/home/sobits/catkin_ws/src/sobit_pro/sobit_pro_description/meshes/body/plate_top.stl" scale="0.001 0.001 0.001"/>
      </geometry>
    </collision> -->
    <inertial>
      <origin rpy="0.0 0.0 1.570796326795" xyz="0.0 0.0 0.0"/>
      <mass value="0.696"/>
      <inertia ixx="1.0" ixy="0.0" ixz="0.0" iyy="1.0" iyz="0.0" izz="1.0"/>
    </inertial>
  </link>


  <joint name="wheel_f_l_steer_base_joint" type="fixed">
    <origin rpy="0.0 0.0 0.7853981633975" xyz="0.14849242404917498 0.14849242404917498 -0.019"/>
    <parent link="plate_middle_link"/>
    <child link="wheel_f_l_steer_base_link"/>
  </joint>
  <link name="wheel_f_l_steer_base_link">
    <visual>
      <origin rpy="1.570796326795 0.0 1.570796326795" xyz="0.0 0.0 0.0"/>
      <geometry>
        <mesh filename="/home/sobits/catkin_ws/src/sobit_pro/sobit_pro_description/meshes/wheel/wheel_base.stl" scale="0.001 0.001 0.001"/>
      </geometry>
      <material name="black"/>
    </visual>
    <!-- <collision>
      <origin rpy="1.570796326795 0.0 1.570796326795" xyz="0.0 0.0 0.0"/>
      <geometry>
        <mesh filename="/home/sobits/catkin_ws/src/sobit_pro/sobit_pro_description/meshes/wheel/wheel_base.stl" scale="0.001 0.001 0.001"/>
      </geometry>
    </collision> -->
    <inertial>
      <origin rpy="1.570796326795 0.0 1.570796326795" xyz="0.0 0.0 0.0"/>
      <mass value="0.100"/>
      <inertia ixx="1.0" ixy="0.0" ixz="0.0" iyy="1.0" iyz="0.0" izz="1.0"/>
    </inertial>
  </link>


  <joint name="wheel_b_l_steer_base_joint" type="fixed">
    <origin rpy="0.0 0.0 2.3561944901925003" xyz="-0.14849242404917498 0.14849242404917498 -0.019"/>
    <parent link="plate_middle_link"/>
    <child link="wheel_b_l_steer_base_link"/>
  </joint>
  <link name="wheel_b_l_steer_base_link">
    <visual>
      <origin rpy="1.570796326795 0.0 1.570796326795" xyz="0.0 0.0 0.0"/>
      <geometry>
        <mesh filename="/home/sobits/catkin_ws/src/sobit_pro/sobit_pro_description/meshes/wheel/wheel_base.stl" scale="0.001 0.001 0.001"/>
      </geometry>
      <material name="black"/>
    </visual>
    <!-- <collision>
      <origin rpy="1.570796326795 0.0 1.570796326795" xyz="0.0 0.0 0.0"/>
      <geometry>
        <mesh filename="/home/sobits/catkin_ws/src/sobit_pro/sobit_pro_description/meshes/wheel/wheel_base.stl" scale="0.001 0.001 0.001"/>
      </geometry>
    </collision> -->
    <inertial>
      <origin rpy="1.570796326795 0.0 1.570796326795" xyz="0.0 0.0 0.0"/>
      <mass value="0.100"/>
      <inertia ixx="1.0" ixy="0.0" ixz="0.0" iyy="1.0" iyz="0.0" izz="1.0"/>
    </inertial>
  </link>


  <joint name="wheel_b_r_steer_base_joint" type="fixed">
    <origin rpy="0.0 0.0 3.9269908169875" xyz="-0.14849242404917498 -0.14849242404917498 -0.019"/>
    <parent link="plate_middle_link"/>
    <child link="wheel_b_r_steer_base_link"/>
  </joint>
  <link name="wheel_b_r_steer_base_link">
    <visual>
      <origin rpy="1.570796326795 0.0 1.570796326795" xyz="0.0 0.0 0.0"/>
      <geometry>
        <mesh filename="/home/sobits/catkin_ws/src/sobit_pro/sobit_pro_description/meshes/wheel/wheel_base.stl" scale="0.001 0.001 0.001"/>
      </geometry>
      <material name="black"/>
    </visual>
    <!-- <collision>
      <origin rpy="1.570796326795 0.0 1.570796326795" xyz="0.0 0.0 0.0"/>
      <geometry>
        <mesh filename="/home/sobits/catkin_ws/src/sobit_pro/sobit_pro_description/meshes/wheel/wheel_base.stl" scale="0.001 0.001 0.001"/>
      </geometry>
    </collision> -->
    <inertial>
      <origin rpy="1.570796326795 0.0 1.570796326795" xyz="0.0 0.0 0.0"/>
      <mass value="0.100"/>
      <inertia ixx="1.0" ixy="0.0" ixz="0.0" iyy="1.0" iyz="0.0" izz="1.0"/>
    </inertial>
  </link>


  <joint name="wheel_f_r_steer_base_joint" type="fixed">
    <origin rpy="0.0 0.0 5.4977871437825" xyz="0.14849242404917498 -0.14849242404917498 -0.019"/>
    <parent link="plate_middle_link"/>
    <child link="wheel_f_r_steer_base_link"/>
  </joint>
  <link name="wheel_f_r_steer_base_link">
    <visual>
      <origin rpy="1.570796326795 0.0 1.570796326795" xyz="0.0 0.0 0.0"/>
      <geometry>
        <mesh filename="/home/sobits/catkin_ws/src/sobit_pro/sobit_pro_description/meshes/wheel/wheel_base.stl" scale="0.001 0.001 0.001"/>
      </geometry>
      <material name="black"/>
    </visual>
    <!-- <collision>
      <origin rpy="1.570796326795 0.0 1.570796326795" xyz="0.0 0.0 0.0"/>
      <geometry>
        <mesh filename="/home/sobits/catkin_ws/src/sobit_pro/sobit_pro_description/meshes/wheel/wheel_base.stl" scale="0.001 0.001 0.001"/>
      </geometry>
    </collision> -->
    <inertial>
      <origin rpy="1.570796326795 0.0 1.570796326795" xyz="0.0 0.0 0.0"/>
      <mass value="0.100"/>
      <inertia ixx="1.0" ixy="0.0" ixz="0.0" iyy="1.0" iyz="0.0" izz="1.0"/>
    </inertial>
  </link>


  <joint name="wheel_f_l_steer_joint" type="revolute">
    <origin rpy="0.0 0.0 0.0" xyz="0.013875 0.0 -0.032"/>
    <parent link="wheel_f_l_steer_base_link"/>
    <child link="wheel_f_l_steer_link"/>
    <axis xyz="0.0 0.0 1.0 "/>
    <limit effort="3.5" lower="-1.570796326795" upper="1.570796326795" velocity="10"/>
    <!-- <dynamics damping="0.2" friction="0" /> -->
  </joint>
  <link name="wheel_f_l_steer_link">
    <visual>
      <origin rpy="1.570796326795 0.0 1.570796326795" xyz="0.0 0.0 0.0"/>
      <geometry>
        <mesh filename="/home/sobits/catkin_ws/src/sobit_pro/sobit_pro_description/meshes/wheel/wheel_steer.stl" scale="0.001 0.001 0.001"/>
      </geometry>
      <material name="black"/>
    </visual>
    <!-- <collision>
      <origin rpy="1.570796326795 0.0 1.570796326795" xyz="0.0 0.0 0.0"/>
      <geometry>
        <mesh filename="/home/sobits/catkin_ws/src/sobit_pro/sobit_pro_description/meshes/wheel/wheel_steer.stl" scale="0.001 0.001 0.001"/>
      </geometry>
    </collision> -->
    <inertial>
      <origin rpy="1.570796326795 0.0 1.570796326795" xyz="0.0 0.0 0.0"/>
      <mass value="0.299"/>
      <inertia ixx="1.0" ixy="0.0" ixz="0.0" iyy="1.0" iyz="0.0" izz="1.0"/>
    </inertial>
  </link>


  <joint name="wheel_b_l_steer_joint" type="revolute">
    <origin rpy="0.0 0.0 0.0" xyz="0.013875 0.0 -0.032"/>
    <parent link="wheel_b_l_steer_base_link"/>
    <child link="wheel_b_l_steer_link"/>
    <axis xyz="0.0 0.0 1.0 "/>
    <limit effort="3.5" lower="-1.570796326795" upper="1.570796326795" velocity="10"/>
    <!-- <dynamics damping="0.2" friction="0" /> -->
  </joint>
  <link name="wheel_b_l_steer_link">
    <visual>
      <origin rpy="1.570796326795 0.0 1.570796326795" xyz="0.0 0.0 0.0"/>
      <geometry>
        <mesh filename="/home/sobits/catkin_ws/src/sobit_pro/sobit_pro_description/meshes/wheel/wheel_steer.stl" scale="0.001 0.001 0.001"/>
      </geometry>
      <material name="black"/>
    </visual>
    <!-- <collision>
      <origin rpy="1.570796326795 0.0 1.570796326795" xyz="0.0 0.0 0.0"/>
      <geometry>
        <mesh filename="/home/sobits/catkin_ws/src/sobit_pro/sobit_pro_description/meshes/wheel/wheel_steer.stl" scale="0.001 0.001 0.001"/>
      </geometry>
    </collision> -->
    <inertial>
      <origin rpy="1.570796326795 0.0 1.570796326795" xyz="0.0 0.0 0.0"/>
      <mass value="0.299"/>
      <inertia ixx="1.0" ixy="0.0" ixz="0.0" iyy="1.0" iyz="0.0" izz="1.0"/>
    </inertial>
  </link>


  <joint name="wheel_b_r_steer_joint" type="revolute">
    <origin rpy="0.0 0.0 0.0" xyz="0.013875 0.0 -0.032"/>
    <parent link="wheel_b_r_steer_base_link"/>
    <child link="wheel_b_r_steer_link"/>
    <axis xyz="0.0 0.0 1.0 "/>
    <limit effort="3.5" lower="-1.570796326795" upper="1.570796326795" velocity="10"/>
    <!-- <dynamics damping="0.2" friction="0" /> -->
  </joint>
  <link name="wheel_b_r_steer_link">
    <visual>
      <origin rpy="1.570796326795 0.0 1.570796326795" xyz="0.0 0.0 0.0"/>
      <geometry>
        <mesh filename="/home/sobits/catkin_ws/src/sobit_pro/sobit_pro_description/meshes/wheel/wheel_steer.stl" scale="0.001 0.001 0.001"/>
      </geometry>
      <material name="black"/>
    </visual>
    <!-- <collision>
      <origin rpy="1.570796326795 0.0 1.570796326795" xyz="0.0 0.0 0.0"/>
      <geometry>
        <mesh filename="/home/sobits/catkin_ws/src/sobit_pro/sobit_pro_description/meshes/wheel/wheel_steer.stl" scale="0.001 0.001 0.001"/>
      </geometry>
    </collision> -->
    <inertial>
      <origin rpy="1.570796326795 0.0 1.570796326795" xyz="0.0 0.0 0.0"/>
      <mass value="0.299"/>
      <inertia ixx="1.0" ixy="0.0" ixz="0.0" iyy="1.0" iyz="0.0" izz="1.0"/>
    </inertial>
  </link>


  <joint name="wheel_f_r_steer_joint" type="revolute">
    <origin rpy="0.0 0.0 0.0" xyz="0.013875 0.0 -0.032"/>
    <parent link="wheel_f_r_steer_base_link"/>
    <child link="wheel_f_r_steer_link"/>
    <axis xyz="0.0 0.0 1.0 "/>
    <limit effort="3.5" lower="-1.570796326795" upper="1.570796326795" velocity="10"/>
    <!-- <dynamics damping="0.2" friction="0" /> -->
  </joint>
  <link name="wheel_f_r_steer_link">
    <visual>
      <origin rpy="1.570796326795 0.0 1.570796326795" xyz="0.0 0.0 0.0"/>
      <geometry>
        <mesh filename="/home/sobits/catkin_ws/src/sobit_pro/sobit_pro_description/meshes/wheel/wheel_steer.stl" scale="0.001 0.001 0.001"/>
      </geometry>
      <material name="black"/>
    </visual>
    <!-- <collision>
      <origin rpy="1.570796326795 0.0 1.570796326795" xyz="0.0 0.0 0.0"/>
      <geometry>
        <mesh filename="/home/sobits/catkin_ws/src/sobit_pro/sobit_pro_description/meshes/wheel/wheel_steer.stl" scale="0.001 0.001 0.001"/>
      </geometry>
    </collision> -->
    <inertial>
      <origin rpy="1.570796326795 0.0 1.570796326795" xyz="0.0 0.0 0.0"/>
      <mass value="0.299"/>
      <inertia ixx="1.0" ixy="0.0" ixz="0.0" iyy="1.0" iyz="0.0" izz="1.0"/>
    </inertial>
  </link>


  <joint name="wheel_f_l_drive_joint" type="continuous">
    <origin rpy="0.0 0.0 0.0" xyz="0.02 0.0 -0.118"/>
    <parent link="wheel_f_l_steer_link"/>
    <child link="wheel_f_l_drive_link"/>
    <axis xyz="-1.0 0.0 0.0 "/>
    <!-- <limit lower="${-M_PI / 2}" upper="${M_PI/2}" effort="10" velocity="10" /> -->
    <limit effort="3.0" velocity="10"/>
    <!-- <dynamics damping="0.2" friction="0" /> -->
  </joint>
  <link name="wheel_f_l_drive_link">
    <visual>
      <origin rpy="1.570796326795 0.0 4.7123889803850005" xyz="0.0 0.0 0.0"/>
      <geometry>
        <mesh filename="/home/sobits/catkin_ws/src/sobit_pro/sobit_pro_description/meshes/wheel/wheel_drive.stl" scale="0.001 0.001 0.001"/>
      </geometry>
      <material name="wheel"/>
    </visual>
    <collision>
      <origin rpy="1.570796326795 0.0 4.7123889803850005" xyz="-0.02 0.0 0.0"/>
      <geometry>
        <cylinder length="0.029" radius="0.072"/>
      </geometry>
    </collision>
    <inertial>
      <origin rpy="1.570796326795 0.0 4.7123889803850005" xyz="0.0 0.0 0.0"/>
      <mass value="0.235"/>
      <inertia ixx="1.0" ixy="0.0" ixz="0.0" iyy="1.0" iyz="0.0" izz="1.0"/>
    </inertial>
  </link>


  <joint name="wheel_b_l_drive_joint" type="continuous">
    <origin rpy="0.0 0.0 0.0" xyz="0.02 0.0 -0.118"/>
    <parent link="wheel_b_l_steer_link"/>
    <child link="wheel_b_l_drive_link"/>
    <axis xyz="-1.0 0.0 0.0 "/>
    <!-- <limit lower="${-M_PI / 2}" upper="${M_PI/2}" effort="10" velocity="10" /> -->
    <limit effort="3.0" velocity="10"/>
    <!-- <dynamics damping="0.2" friction="0" /> -->
  </joint>
  <link name="wheel_b_l_drive_link">
    <visual>
      <origin rpy="1.570796326795 0.0 4.7123889803850005" xyz="0.0 0.0 0.0"/>
      <geometry>
        <mesh filename="/home/sobits/catkin_ws/src/sobit_pro/sobit_pro_description/meshes/wheel/wheel_drive.stl" scale="0.001 0.001 0.001"/>
      </geometry>
      <material name="wheel"/>
    </visual>
    <collision>
      <origin rpy="1.570796326795 0.0 4.7123889803850005" xyz="-0.02 0.0 0.0"/>
      <geometry>
        <cylinder length="0.029" radius="0.072"/>
      </geometry>
    </collision>
    <inertial>
      <origin rpy="1.570796326795 0.0 4.7123889803850005" xyz="0.0 0.0 0.0"/>
      <mass value="0.235"/>
      <inertia ixx="1.0" ixy="0.0" ixz="0.0" iyy="1.0" iyz="0.0" izz="1.0"/>
    </inertial>
  </link>


  <joint name="wheel_b_r_drive_joint" type="continuous">
    <origin rpy="0.0 0.0 0.0" xyz="0.02 0.0 -0.118"/>
    <parent link="wheel_b_r_steer_link"/>
    <child link="wheel_b_r_drive_link"/>
    <axis xyz="-1.0 0.0 0.0 "/>
    <!-- <limit lower="${-M_PI / 2}" upper="${M_PI/2}" effort="10" velocity="10" /> -->
    <limit effort="3.0" velocity="10"/>
    <!-- <dynamics damping="0.2" friction="0" /> -->
  </joint>
  <link name="wheel_b_r_drive_link">
    <visual>
      <origin rpy="1.570796326795 0.0 4.7123889803850005" xyz="0.0 0.0 0.0"/>
      <geometry>
        <mesh filename="/home/sobits/catkin_ws/src/sobit_pro/sobit_pro_description/meshes/wheel/wheel_drive.stl" scale="0.001 0.001 0.001"/>
      </geometry>
      <material name="wheel"/>
    </visual>
    <collision>
      <origin rpy="1.570796326795 0.0 4.7123889803850005" xyz="-0.02 0.0 0.0"/>
      <geometry>
        <cylinder length="0.029" radius="0.072"/>
      </geometry>
    </collision>
    <inertial>
      <origin rpy="1.570796326795 0.0 4.7123889803850005" xyz="0.0 0.0 0.0"/>
      <mass value="0.235"/>
      <inertia ixx="1.0" ixy="0.0" ixz="0.0" iyy="1.0" iyz="0.0" izz="1.0"/>
    </inertial>
  </link>


  <joint name="wheel_f_r_drive_joint" type="continuous">
    <origin rpy="0.0 0.0 0.0" xyz="0.02 0.0 -0.118"/>
    <parent link="wheel_f_r_steer_link"/>
    <child link="wheel_f_r_drive_link"/>
    <axis xyz="-1.0 0.0 0.0 "/>
    <!-- <limit lower="${-M_PI / 2}" upper="${M_PI/2}" effort="10" velocity="10" /> -->
    <limit effort="3.0" velocity="10"/>
    <!-- <dynamics damping="0.2" friction="0" /> -->
  </joint>
  <link name="wheel_f_r_drive_link">
    <visual>
      <origin rpy="1.570796326795 0.0 4.7123889803850005" xyz="0.0 0.0 0.0"/>
      <geometry>
        <mesh filename="/home/sobits/catkin_ws/src/sobit_pro/sobit_pro_description/meshes/wheel/wheel_drive.stl" scale="0.001 0.001 0.001"/>
      </geometry>
      <material name="wheel"/>
    </visual>
    <collision>
      <origin rpy="1.570796326795 0.0 4.7123889803850005" xyz="-0.02 0.0 0.0"/>
      <geometry>
        <cylinder length="0.029" radius="0.072"/>
      </geometry>
    </collision>
    <inertial>
      <origin rpy="1.570796326795 0.0 4.7123889803850005" xyz="0.0 0.0 0.0"/>
      <mass value="0.235"/>
      <inertia ixx="1.0" ixy="0.0" ixz="0.0" iyy="1.0" iyz="0.0" izz="1.0"/>
    </inertial>
  </link>


  <joint name="cover_joint" type="fixed">
    <origin rpy="0.0 0.0 0.0" xyz="0.179108 0.0 -0.034"/>
    <parent link="plate_top_link"/>
    <child link="cover_link"/>
  </joint>
  <link name="cover_link">
    <visual>
      <origin rpy="1.570796326795 0.0 1.570796326795" xyz="0.0 0.0 0.0"/>
      <geometry>
        <mesh filename="/home/sobits/catkin_ws/src/sobit_pro/sobit_pro_description/meshes/body/cover.stl" scale="0.001 0.001 0.001"/>
      </geometry>
      <material name="blue"/>
    </visual>
    <collision>
      <origin rpy="1.570796326795 0.0 1.570796326795" xyz="0.0 0.0 0.0"/>
      <geometry>
        <mesh filename="/home/sobits/catkin_ws/src/sobit_pro/sobit_pro_description/meshes/body/cover.stl" scale="0.001 0.001 0.001"/>
      </geometry>
    </collision>
    <inertial>
      <origin rpy="1.570796326795 0.0 1.570796326795" xyz="0.0 0.0 0.0"/>
      <mass value="0.1"/>
      <inertia ixx="0.0001" ixy="0.0" ixz="0.0" iyy="0.0001" iyz="0.0" izz="0.0001"/>
    </inertial>
  </link>


  <joint name="back_base_joint" type="fixed">
    <parent link="plate_top_link"/>
    <child link="back_base_link"/>
    <origin rpy="0.0 0.0 0.0" xyz="0.0 0.0 0.0"/>
  </joint>
  <link name="back_base_link">
    <visual>
      <origin rpy="0.0 0.0 3.14159265359" xyz="0.0 0.0 0.0"/>
      <geometry>
        <mesh filename="/home/sobits/catkin_ws/src/sobit_pro/sobit_pro_description/meshes/back/back_base.stl" scale="0.001 0.001 0.001"/>
      </geometry>
      <material name="grey"/>
    </visual>
    <collision>
      <origin rpy="0.0 0.0 3.14159265359" xyz="0.0 0.0 0.0"/>
      <geometry>
        <mesh filename="/home/sobits/catkin_ws/src/sobit_pro/sobit_pro_description/meshes/back/back_base.stl" scale="0.001 0.001 0.001"/>
      </geometry>
    </collision>
    <inertial>
      <origin rpy="0.0 0.0 3.14159265359" xyz="0.0 0.0 0.0"/>
      <mass value="0.516"/>
      <inertia ixx="1.0" ixy="0.0" ixz="0.0" iyy="1.0" iyz="0.0" izz="1.0"/>
    </inertial>
  </link>


  <joint name="head_camera_base_joint" type="fixed">
    <parent link="back_base_link"/>
    <child link="head_camera_base_link"/>
    <origin rpy="0.0 0.0 0.0" xyz="0.0900 0.0 0.5270"/>
  </joint>
  <link name="head_camera_base_link">
    <visual>
      <origin rpy="1.570796326795 0.0 1.570796326795" xyz="0.0 0.0 0.0"/>
      <geometry>
        <mesh filename="/home/sobits/catkin_ws/src/sobit_pro/sobit_pro_description/meshes/head/head_camera_base.stl" scale="0.001 0.001 0.001"/>
      </geometry>
      <material name="black"/>
    </visual>
    <!-- <collision>
      <origin rpy="1.570796326795 0.0 1.570796326795" xyz="0.0 0.0 0.0"/>
      <geometry>
        <mesh filename="/home/sobits/catkin_ws/src/sobit_pro/sobit_pro_description/meshes/head/head_camera_base.stl" scale="0.001 0.001 0.001"/>
      </geometry>
    </collision> -->
    <inertial>
      <origin rpy="1.570796326795 0.0 1.570796326795" xyz="0.0 0.0 0.0"/>
      <mass value="0.100"/>
      <inertia ixx="1.0" ixy="0.0" ixz="0.0" iyy="1.0" iyz="0.0" izz="1.0"/>
    </inertial>
  </link>


  <joint name="head_camera_pan_joint" type="fixed">
  <!-- <joint name="head_camera_pan_joint" type="revolute"> -->
    <parent link="head_camera_base_link"/>
    <child link="head_camera_pan_link"/>
    <origin rpy="0.0 0.0 0.0" xyz="0.03985 0.0 0.0190"/>
    <axis xyz="0 0 1"/>
    <!-- <limit effort="30" lower="-1.570796326795" upper="1.570796326795" velocity="1.570796326795"/> -->
  </joint>
  <link name="head_camera_pan_link">
    <visual>
      <origin rpy="0.0 0.0 1.570796326795" xyz="0.0 0.0 0.0"/>
      <geometry>
        <mesh filename="/home/sobits/catkin_ws/src/sobit_pro/sobit_pro_description/meshes/head/head_camera_pan.stl" scale="0.001 0.001 0.001"/>
      </geometry>
      <material name="black"/>
    </visual>
    <!-- <collision>
      <origin rpy="0.0 0.0 1.570796326795" xyz="0.0 0.0 0.0"/>
      <geometry>
        <mesh filename="/home/sobits/catkin_ws/src/sobit_pro/sobit_pro_description/meshes/head/head_camera_pan.stl" scale="0.001 0.001 0.001"/>
      </geometry>
    </collision> -->
    <inertial>
      <origin rpy="0.0 0.0 1.570796326795" xyz="0.0 0.0 0.0"/>
      <mass value="0.090"/>
      <inertia ixx="1.0" ixy="0.0" ixz="0.0" iyy="1.0" iyz="0.0" izz="1.0"/>
    </inertial>
  </link>


  <joint name="head_camera_tilt_joint" type="fixed">
  <!-- <joint name="head_camera_tilt_joint" type="revolute"> -->
    <parent link="head_camera_pan_link"/>
    <child link="head_camera_tilt_link"/>
    <origin rpy="0.0 0.52359877559 0.0" xyz="0.0 0.0 0.0405"/>
    <axis xyz="0 -1 0"/>
    <!-- <limit effort="30" lower="-1.570796326795" upper="1.570796326795" velocity="1.570796326795"/> -->
  </joint>
  <link name="head_camera_tilt_link">
    <visual>
      <origin rpy="0.0 0.0 1.570796326795" xyz="0.0 0.0 0.0"/>
      <geometry>
        <mesh filename="/home/sobits/catkin_ws/src/sobit_pro/sobit_pro_description/meshes/head/head_camera_tilt.stl" scale="0.001 0.001 0.001"/>
      </geometry>
      <material name="black"/>
    </visual>
    <collision>
      <origin rpy="0.0 0.0 1.570796326795" xyz="0.0 0.0 0.0"/>
      <geometry>
        <mesh filename="/home/sobits/catkin_ws/src/sobit_pro/sobit_pro_description/meshes/head/head_camera_tilt.stl" scale="0.001 0.001 0.001"/>
      </geometry>
    </collision>
    <inertial>
      <origin rpy="0.0 0.0 1.570796326795" xyz="0.0 0.0 0.0"/>
      <mass value="0.050"/>
      <inertia ixx="1.0" ixy="0.0" ixz="0.0" iyy="1.0" iyz="0.0" izz="1.0"/>
    </inertial>
  </link>


  <joint name="mic_base_joint" type="fixed">
    <parent link="back_base_link"/>
    <child link="mic_base_link"/>
    <origin rpy="0.0 0.0 0.0" xyz="0.0 0.0 0.5400"/>
  </joint>
  <link name="mic_base_link">
    <visual>
      <origin rpy="1.570796326795 0.0 3.14159265359" xyz="0.0 0.0 0.0"/>
      <geometry>
        <mesh filename="/home/sobits/catkin_ws/src/sobit_pro/sobit_pro_description/meshes/sensor/mic_base.stl" scale="0.001 0.001 0.001"/>
      </geometry>
      <material name="black"/>
    </visual>
    <!-- <collision>
      <origin rpy="1.570796326795 0.0 3.14159265359" xyz="0.0 0.0 0.0"/>
      <geometry>
        <mesh filename="/home/sobits/catkin_ws/src/sobit_pro/sobit_pro_description/meshes/sensor/mic_base.stl" scale="0.001 0.001 0.001"/>
      </geometry>
      <material name="black"/>
    </collision> -->
    <inertial>
      <origin rpy="1.570796326795 0.0 3.14159265359" xyz="0.0 0.0 0.0"/>
      <mass value="0.100"/>
      <inertia ixx="1.0" ixy="0.0" ixz="0.0" iyy="1.0" iyz="0.0" izz="1.0"/>
    </inertial>
  </link>


  <joint name="mic_joint" type="fixed">
    <parent link="mic_base_link"/>
    <child link="mic_link"/>
    <origin rpy="0.0 0.0 0.0" xyz="0.0 -0.099 0.0240"/>
  </joint>
  <link name="mic_link">
    <visual>
      <origin rpy="1.570796326795 0.0 3.14159265359" xyz="0.0 0.0 0.0"/>
      <geometry>
        <mesh filename="/home/sobits/catkin_ws/src/sobit_pro/sobit_pro_description/meshes/sensor/mic.stl" scale="0.001 0.001 0.001"/>
      </geometry>
      <material name="black"/>
    </visual>
    <!-- <collision>
      <origin rpy="1.570796326795 0.0 3.14159265359" xyz="0.0 0.0 0.0"/>
      <geometry>
        <mesh filename="/home/sobits/catkin_ws/src/sobit_pro/sobit_pro_description/meshes/sensor/mic.stl" scale="0.001 0.001 0.001"/>
      </geometry>
      <material name="black"/>
    </collision> -->
    <inertial>
      <origin rpy="1.570796326795 0.0 3.14159265359" xyz="0.0 0.0 0.0"/>
      <mass value="0.272"/>
      <inertia ixx="1.0" ixy="0.0" ixz="0.0" iyy="1.0" iyz="0.0" izz="1.0"/>
    </inertial>
  </link>


  <joint name="arm_base_joint" type="fixed">
    <parent link="plate_top_link"/>
    <child link="arm_base_link"/>
    <origin rpy="0.0 0.0 0.0" xyz="0.065 0.0 0.0"/>
  </joint>
  <link name="arm_base_link">
    <visual>
      <origin rpy="1.570796326795 0.0 0.0" xyz="0.0 0.0 0.0"/>
      <geometry>
        <mesh filename="/home/sobits/catkin_ws/src/sobit_pro/sobit_pro_description/meshes/arm/arm_base.stl" scale="0.001 0.001 0.001"/>
      </geometry>
      <material name="black"/>
    </visual>
    <collision>
      <origin rpy="1.570796326795 0.0 0.0" xyz="0.0 0.0 0.0"/>
      <geometry>
        <mesh filename="/home/sobits/catkin_ws/src/sobit_pro/sobit_pro_description/meshes/arm/arm_base.stl" scale="0.001 0.001 0.001"/>
      </geometry>
    </collision>
    <inertial>
      <origin rpy="1.570796326795 0.0 0.0" xyz="0.0 0.0 0.0"/>
      <mass value="0.508"/>
      <inertia ixx="1.0" ixy="0.0" ixz="0.0" iyy="1.0" iyz="0.0" izz="1.0"/>
    </inertial>
  </link>


  <joint name="arm_shoulder_1_tilt_joint" type="revolute">
    <parent link="arm_base_link"/>
    <child link="arm_shoulder_1_tilt_link"/>
    <origin rpy="0.0 -1.57079632679 0.0 " xyz="0.1560 0.0 0.0215"/>
    <axis xyz="0.0 -1.0 0.0 "/>
    <limit effort="20" lower="-3.14159265359" upper="0.0" velocity="10"/>
    <!-- <limit effort="20" lower="-1.570796326795" upper="1.570796326795" velocity="10"/> -->
    <!-- <dynamics damping="0.2" friction="0" /> -->
  </joint>
  <link name="arm_shoulder_1_tilt_link">
    <visual>
      <origin rpy="1.570796326795 0.0 1.570796326795" xyz="0.0 0.0 0.0"/>
      <geometry>
        <mesh filename="/home/sobits/catkin_ws/src/sobit_pro/sobit_pro_description/meshes/arm/arm_upper.stl" scale="0.001 0.001 0.001"/>
      </geometry>
      <material name="black"/>
    </visual>
    <collision>
      <origin rpy="1.570796326795 0.0 1.570796326795" xyz="0.0 0.0 0.0"/>
      <geometry>
        <mesh filename="/home/sobits/catkin_ws/src/sobit_pro/sobit_pro_description/meshes/arm/arm_upper.stl" scale="0.001 0.001 0.001"/>
      </geometry>
    </collision>
    <inertial>
      <origin rpy="1.570796326795 0.0 1.570796326795" xyz="0.0 0.0 0.0"/>
      <mass value="0.302"/>
      <inertia ixx="1.0" ixy="0.0" ixz="0.0" iyy="1.0" iyz="0.0" izz="1.0"/>
    </inertial>
  </link>


  <!-- <joint name="arm_shoulder_2_tilt_joint" type="fixed">
    <parent link="arm_base_link"/>
    <child link="arm_shoulder_2_tilt_link"/>
    <origin rpy="0.0 0.0 3.14159265359" xyz="0.1560 0.0 0.0215"/>
    <axis xyz="0.0 1.0 0.0 "/>
    <mimic joint="arm_shoulder_1_tilt_joint" multiplier="1" offset="0"/>
    <limit effort="10" lower="-1.570796326795" upper="1.570796326795" velocity="10"/>
    <dynamics damping="0.2" friction="0" />
  </joint>
  <link name="arm_shoulder_2_tilt_link"/> -->


  <joint name="arm_elbow_upper_1_tilt_joint" type="revolute">
    <parent link="arm_shoulder_1_tilt_link"/>
    <child link="arm_elbow_upper_1_tilt_link"/>
    <origin rpy="0.0 1.57079632679 0.0" xyz="0.1500 0.0 0.0"/>
    <axis xyz="0.0 -1.0 0.0 "/>
    <limit effort="7.0" lower="0.0" upper="3.14159265359" velocity="10"/>
    <!-- <limit effort="7.0" lower="-1.570796326795" upper="1.570796326795" velocity="10"/> -->
    <!-- <dynamics damping="0.2" friction="0" /> -->
  </joint>
  <link name="arm_elbow_upper_1_tilt_link">
    <visual>
      <origin rpy="1.570796326795 0.0 1.570796326795" xyz="0.0 0.0 0.0"/>
      <geometry>
        <mesh filename="/home/sobits/catkin_ws/src/sobit_pro/sobit_pro_description/meshes/arm/arm_inner.stl" scale="0.001 0.001 0.001"/>
      </geometry>
      <material name="black"/>
    </visual>
    <collision>
      <origin rpy="1.570796326795 0.0 1.570796326795" xyz="0.0 0.0 0.0"/>
      <geometry>
        <mesh filename="/home/sobits/catkin_ws/src/sobit_pro/sobit_pro_description/meshes/arm/arm_inner.stl" scale="0.001 0.001 0.001"/>
      </geometry>
    </collision>
    <inertial>
      <origin rpy="1.570796326795 0.0 1.570796326795" xyz="0.0 0.0 0.0"/>
      <mass value="0.186"/>
      <inertia ixx="1.0" ixy="0.0" ixz="0.0" iyy="1.0" iyz="0.0" izz="1.0"/>
    </inertial>
  </link>


  <!-- <joint name="arm_elbow_upper_2_tilt_joint" type="fixed">
    <parent link="arm_shoulder_1_tilt_link"/>
    <child link="arm_elbow_upper_2_tilt_link"/>
    <origin rpy="0.0 0.0 3.14159265359" xyz="0.1500 0.0 0.0"/>
    <axis xyz="0.0 1.0 0.0 "/>
    <mimic joint="arm_elbow_upper_1_tilt_joint" multiplier="1" offset="0"/>
    <limit effort="3.5" lower="-1.570796326795" upper="1.570796326795" velocity="10"/>
    <dynamics damping="0.2" friction="0" />
  </joint>
  <link name="arm_elbow_upper_2_tilt_link"/> -->


  <joint name="arm_elbow_lower_tilt_joint" type="revolute">
    <parent link="arm_elbow_upper_1_tilt_link"/>
    <child link="arm_elbow_lower_tilt_link"/>
    <origin rpy="0.0 0.0 0.0" xyz="0.1500 0.0 0.0"/>
    <axis xyz="0.0 -1.0 0.0 "/>
    <limit effort="3.5" lower="-1.570796326795" upper="1.570796326795" velocity="10"/>
    <!-- <dynamics damping="0.2" friction="0" /> -->
  </joint>
  <link name="arm_elbow_lower_tilt_link">
    <visual>
      <origin rpy="1.570796326795 0.0 1.570796326795" xyz="0.0 0.0 0.0"/>
      <geometry>
        <mesh filename="/home/sobits/catkin_ws/src/sobit_pro/sobit_pro_description/meshes/arm/arm_elbow_lower_tilt.stl" scale="0.001 0.001 0.001"/>
      </geometry>
      <material name="black"/>
    </visual>
    <collision>
      <origin rpy="1.570796326795 0.0 1.570796326795" xyz="0.0 0.0 0.0"/>
      <geometry>
        <mesh filename="/home/sobits/catkin_ws/src/sobit_pro/sobit_pro_description/meshes/arm/arm_elbow_lower_tilt.stl" scale="0.001 0.001 0.001"/>
      </geometry>
    </collision>
    <inertial>
      <origin rpy="1.570796326795 0.0 1.570796326795" xyz="0.0 0.0 0.0"/>
      <mass value="0.08"/>
      <inertia ixx="1.0" ixy="0.0" ixz="0.0" iyy="1.0" iyz="0.0" izz="1.0"/>
    </inertial>
  </link>


  <joint name="arm_elbow_lower_pan_joint" type="revolute">
    <parent link="arm_elbow_lower_tilt_link"/>
    <child link="arm_elbow_lower_pan_link"/>
    <origin rpy="-1.57079632679 0.0 0.0" xyz="0.028 0.0 0.0"/>
    <axis xyz="-1.0 0.0 0.0 "/>
    <limit effort="3.5" lower="-1.570796326795" upper="1.570796326795" velocity="10"/>
    <!-- <limit effort="3.5" lower="-3.14159265359" upper="3.14159265359" velocity="10"/> -->
    <!-- <dynamics damping="0.2" friction="0" /> -->
  </joint>
  <link name="arm_elbow_lower_pan_link">
    <visual>
      <origin rpy="1.570796326795 0.0 1.570796326795" xyz="0.0 0.0 0.0"/>
      <geometry>
        <mesh filename="/home/sobits/catkin_ws/src/sobit_pro/sobit_pro_description/meshes/arm/arm_elbow_lower_pan.stl" scale="0.001 0.001 0.001"/>
      </geometry>
      <material name="black"/>
    </visual>
    <collision>
      <origin rpy="1.570796326795 0.0 1.570796326795" xyz="0.0 0.0 0.0"/>
      <geometry>
        <mesh filename="/home/sobits/catkin_ws/src/sobit_pro/sobit_pro_description/meshes/arm/arm_elbow_lower_pan.stl" scale="0.001 0.001 0.001"/>
      </geometry>
    </collision>
    <inertial>
      <origin rpy="1.570796326795 0.0 1.570796326795" xyz="0.0 0.0 0.0"/>
      <mass value="0.294"/>
      <inertia ixx="1.0" ixy="0.0" ixz="0.0" iyy="1.0" iyz="0.0" izz="1.0"/>
    </inertial>
  </link>


  <joint name="arm_wrist_tilt_joint" type="revolute">
    <parent link="arm_elbow_lower_pan_link"/>
    <child link="arm_wrist_tilt_link"/>
    <origin rpy="0.0 0.0 0.0" xyz="0.122009 0.0 0.0"/>
    <axis xyz="0.0 -1.0 0.0"/>
    <limit effort="3.5" lower="-1.570796326795" upper="1.570796326795" velocity="10"/>
    <!-- <dynamics damping="0.2" friction="0" /> -->
  </joint>
  <link name="arm_wrist_tilt_link"/>


  <joint name="hand_base_joint" type="fixed">
    <parent link="arm_wrist_tilt_link"/>
    <child link="hand_base_link"/>
    <origin rpy="0.0 0.0 0.0" xyz="0.0 0.0 0.0"/>
  </joint>
  <link name="hand_base_link">
    <visual>
      <origin rpy="1.570796326795 0.0 1.570796326795" xyz="0.0 0.0 0.0"/>
      <geometry>
        <mesh filename="/home/sobits/catkin_ws/src/sobit_pro/sobit_pro_description/meshes/hand/hand_base.stl" scale="0.001 0.001 0.001"/>
      </geometry>
      <material name="black"/>
    </visual>
    <collision>
      <origin rpy="1.570796326795 0.0 1.570796326795" xyz="0.0 0.0 0.0"/>
      <geometry>
        <mesh filename="/home/sobits/catkin_ws/src/sobit_pro/sobit_pro_description/meshes/hand/hand_base.stl" scale="0.001 0.001 0.001"/>
      </geometry>
    </collision>
    <inertial>
      <origin rpy="1.570796326795 0.0 1.570796326795" xyz="0.0 0.0 0.0"/>
      <mass value="0.02"/>
      <inertia ixx="1.0" ixy="0.0" ixz="0.0" iyy="1.0" iyz="0.0" izz="1.0"/>
    </inertial>
  </link>


  <joint name="tray_joint" type="fixed">
    <parent link="arm_wrist_tilt_link"/>
    <child link="tray_link"/>
    <origin rpy="0.0 0.0 0.0" xyz="0.42276158 0.0 0.0"/>
  </joint>
  <link name="tray_link">
    <visual>
      <origin rpy="1.57079632679 0.0 0.0" xyz="0.0 0.01402103 0.0"/>
      <geometry>
        <mesh filename="/home/sobits/catkin_ws/src/sobit_pro/sobit_pro_description/meshes/tray/tray_full.stl" scale="0.001 0.001 0.001"/>
      </geometry>
      <material name="brown"/>
    </visual>
    <collision>
      <origin rpy="1.57079632679 0.0 0.0" xyz="0.0 0.007 0.01402103"/>
      <geometry>
        <box size="0.46 0.46 0.014"/>
      </geometry>
    </collision>
    <inertial>
      <origin rpy="1.570796326795 0.0 1.570796326795" xyz="0.42276158 0.0 0.01402103"/>
      <mass value="0.08"/>
      <inertia ixx="1.0" ixy="0.0" ixz="0.0" iyy="1.0" iyz="0.0" izz="1.0"/>
    </inertial>
  </link>


  <joint name="tray_tf_joint" type="fixed">
    <parent link="tray_link"/>
    <child link="tray_tf_link"/>
    <origin rpy="1.570796326795 0.0 0.0" xyz="0.0 0.0 0.0"/>
  </joint>
  <link name="tray_tf_link"/>


  <joint name="hand_joint" type="fixed">
    <parent link="hand_base_link"/>
    <child link="hand_link"/>
    <origin rpy="0.0 0.0 0.0" xyz="0.0631932 -0.0151495 0.0222231"/>
    <axis xyz="0.0 0.0 1.0"/>
    <!-- <limit effort="1" lower="-1.570796326795" upper="0" velocity="1"/> -->
  </joint>
  <link name="hand_link"/>


  <joint name="hand_inner_l_joint" type="fixed">
    <parent link="hand_base_link"/>
    <child link="hand_inner_l_link"/>
    <origin rpy="0.0 0.0 0.28965702432" xyz="0.0631932 0.0151495 0.0372231"/>
    <axis xyz="0.0 0.0 -1.0"/>
    <!-- <mimic joint="hand_joint" multiplier="1.0" offset="0"/> -->
    <!-- <limit effort="1" lower="-1.570796326795" upper="0" velocity="1"/> -->
  </joint>
  <link name="hand_inner_l_link">
    <visual>
      <origin rpy="0.0 0.0 1.570796326795" xyz="0.0 0.0 0.0"/>
      <geometry>
        <mesh filename="/home/sobits/catkin_ws/src/sobit_pro/sobit_pro_description/meshes/hand/hand_inner_l.stl" scale="0.001 0.001 0.001"/>
      </geometry>
      <material name="black"/>
    </visual>
    <collision>
      <origin rpy="0.0 0.0 1.570796326795" xyz="0.0 0.0 0.0"/>
      <geometry>
        <mesh filename="/home/sobits/catkin_ws/src/sobit_pro/sobit_pro_description/meshes/hand/hand_inner_l.stl" scale="0.001 0.001 0.001"/>
      </geometry>
    </collision>
    <inertial>
      <origin rpy="0.0 0.0 0.0" xyz="0.0 0.0 0.0"/>
      <mass value="0.02"/>
      <inertia ixx="1.0" ixy="0.0" ixz="0.0" iyy="1.0" iyz="0.0" izz="1.0"/>
    </inertial>
  </link>


  <joint name="hand_inner_r_joint" type="fixed">
    <parent link="hand_base_link"/>
    <child link="hand_inner_r_link"/>
    <origin rpy="0.0 0.0 -0.28965702432" xyz="0.0631932 -0.0151495 0.0372231"/>
    <axis xyz="0.0 0.0 1.0"/>
    <!-- <mimic joint="hand_joint" multiplier="1.0" offset="0"/> -->
    <!-- <limit effort="1" lower="-1.570796326795" upper="0" velocity="1"/> -->
  </joint>
  <link name="hand_inner_r_link">
    <visual>
      <origin rpy="0.0 0.0 1.570796326795" xyz="0.0 0.0 0.0"/>
      <geometry>
        <mesh filename="/home/sobits/catkin_ws/src/sobit_pro/sobit_pro_description/meshes/hand/hand_inner_r.stl" scale="0.001 0.001 0.001"/>
      </geometry>
      <material name="black"/>
    </visual>
    <collision>
      <origin rpy="0.0 0.0 1.570796326795" xyz="0.0 0.0 0.0"/>
      <geometry>
        <mesh filename="/home/sobits/catkin_ws/src/sobit_pro/sobit_pro_description/meshes/hand/hand_inner_r.stl" scale="0.001 0.001 0.001"/>
      </geometry>
    </collision>
    <inertial>
      <origin rpy="0.0 0.0 0.0" xyz="0.0 0.0 0.0"/>
      <mass value="0.02"/>
      <inertia ixx="1.0" ixy="0.0" ixz="0.0" iyy="1.0" iyz="0.0" izz="1.0"/>
    </inertial>
  </link>


  <joint name="hand_outer_l_joint" type="fixed">
    <parent link="hand_base_link"/>
    <child link="hand_outer_l_link"/>
    <origin rpy="0.0 0.0 0.31421864146" xyz="0.043193 0.04015 0.0282231"/>
    <axis xyz="0.0 0.0 -1.0"/>
    <!-- <mimic joint="hand_joint" multiplier="1.0" offset="0"/> -->
    <!-- <limit effort="1" lower="-1.570796326795" upper="0" velocity="1"/> -->
  </joint>
  <link name="hand_outer_l_link">
    <visual>
      <origin rpy="0.0 0.0 1.570796326795" xyz="0.0 0.0 0.0"/>
      <geometry>
        <mesh filename="/home/sobits/catkin_ws/src/sobit_pro/sobit_pro_description/meshes/hand/hand_outer_l.stl" scale="0.001 0.001 0.001"/>
      </geometry>
      <material name="black"/>
    </visual>
    <collision>
      <origin rpy="0.0 0.0 1.570796326795" xyz="0.0 0.0 0.0"/>
      <geometry>
        <mesh filename="/home/sobits/catkin_ws/src/sobit_pro/sobit_pro_description/meshes/hand/hand_outer_l.stl" scale="0.001 0.001 0.001"/>
      </geometry>
    </collision>
    <inertial>
      <origin rpy="0.0 0.0 0.0" xyz="0.0 0.0 0.0"/>
      <mass value="0.02"/>
      <inertia ixx="1.0" ixy="0.0" ixz="0.0" iyy="1.0" iyz="0.0" izz="1.0"/>
    </inertial>
  </link>


  <joint name="hand_outer_r_joint" type="fixed">
    <parent link="hand_base_link"/>
    <child link="hand_outer_r_link"/>
    <origin rpy="0.0 0.0 -0.31421864146" xyz="0.043193 -0.04015 0.0282231"/>
    <axis xyz="0.0 0.0 1.0"/>
    <!-- <mimic joint="hand_joint" multiplier="1.0" offset="0"/> -->
    <!-- <limit effort="1" lower="-1.570796326795" upper="0" velocity="1"/> -->
  </joint>
  <link name="hand_outer_r_link">
    <visual>
      <origin rpy="0.0 0.0 1.570796326795" xyz="0.0 0.0 0.0"/>
      <geometry>
        <mesh filename="/home/sobits/catkin_ws/src/sobit_pro/sobit_pro_description/meshes/hand/hand_outer_r.stl" scale="0.001 0.001 0.001"/>
      </geometry>
      <material name="black"/>
    </visual>
    <collision>
      <origin rpy="0.0 0.0 1.570796326795" xyz="0.0 0.0 0.0"/>
      <geometry>
        <mesh filename="/home/sobits/catkin_ws/src/sobit_pro/sobit_pro_description/meshes/hand/hand_outer_r.stl" scale="0.001 0.001 0.001"/>
      </geometry>
    </collision>
    <inertial>
      <origin rpy="0.0 0.0 0.0" xyz="0.0 0.0 0.0"/>
      <mass value="0.02"/>
      <inertia ixx="1.0" ixy="0.0" ixz="0.0" iyy="1.0" iyz="0.0" izz="1.0"/>
    </inertial>
  </link>


  <joint name="hand_finger_l_joint" type="fixed">
    <parent link="hand_outer_l_link"/>
    <child link="hand_finger_l_link"/>
    <origin rpy="0.0 0.0 -0.30038308486" xyz="0.1040 0.0 -0.0190"/>
    <axis xyz="0.0 0.0 1.0"/>
    <!-- <mimic joint="hand_joint" multiplier="1.0" offset="0"/> -->
    <!-- <limit effort="1" lower="-1.570796326795" upper="0" velocity="1"/> -->
  </joint>
  <link name="hand_finger_l_link">
    <visual>
      <origin rpy="0.0 0.0 1.570796326795" xyz="0.0 0.0 0.0"/>
      <geometry>
        <mesh filename="/home/sobits/catkin_ws/src/sobit_pro/sobit_pro_description/meshes/hand/hand_finger_l.stl" scale="0.001 0.001 0.001"/>
      </geometry>
      <material name="black"/>
    </visual>
    <collision>
      <origin rpy="0.0 0.0 1.570796326795" xyz="0.0 0.0 0.0"/>
      <geometry>
        <mesh filename="/home/sobits/catkin_ws/src/sobit_pro/sobit_pro_description/meshes/hand/hand_finger_l.stl" scale="0.001 0.001 0.001"/>
      </geometry>
    </collision>
    <inertial>
      <origin rpy="0.0 0.0 0.0" xyz="0.0 0.0 0.0"/>
      <mass value="0.04"/>
      <inertia ixx="1.0" ixy="0.0" ixz="0.0" iyy="1.0" iyz="0.0" izz="1.0"/>
    </inertial>
  </link>


  <joint name="hand_finger_r_joint" type="fixed">
    <parent link="hand_outer_r_link"/>
    <child link="hand_finger_r_link"/>
    <origin rpy="0.0 0.0 0.30038308486" xyz="0.1040 0.0 -0.0190"/>
    <axis xyz="0.0 0.0 -1.0"/>
    <!-- <mimic joint="hand_joint" multiplier="1.0" offset="0"/> -->
    <!-- <limit effort="1" lower="-1.570796326795" upper="0" velocity="1"/> -->
  </joint>
  <link name="hand_finger_r_link">
    <visual>
      <origin rpy="0.0 0.0 1.570796326795" xyz="0.0 0.0 0.0"/>
      <geometry>
        <mesh filename="/home/sobits/catkin_ws/src/sobit_pro/sobit_pro_description/meshes/hand/hand_finger_r.stl" scale="0.001 0.001 0.001"/>
      </geometry>
      <material name="black"/>
    </visual>
    <collision>
      <origin rpy="0.0 0.0 1.570796326795" xyz="0.0 0.0 0.0"/>
      <geometry>
        <mesh filename="/home/sobits/catkin_ws/src/sobit_pro/sobit_pro_description/meshes/hand/hand_finger_r.stl" scale="0.001 0.001 0.001"/>
      </geometry>
    </collision>
    <inertial>
      <origin rpy="0.0 0.0 0.0" xyz="0.0 0.0 0.0"/>
      <mass value="0.04"/>
      <inertia ixx="1.0" ixy="0.0" ixz="0.0" iyy="1.0" iyz="0.0" izz="1.0"/>
    </inertial>
  </link>


  <joint name="lidar_base_joint" type="fixed">
    <parent link="plate_bottom_link"/>
    <child link="lidar_base_link"/>
    <origin rpy="0.0 0.0 0.0" xyz="0.1500 0.0 0.0"/>
  </joint>
  <link name="lidar_base_link">
    <visual>
      <origin rpy="1.570796326795 0.0 3.14159265359" xyz="0.0 0.0 0.0"/>
      <geometry>
        <mesh filename="/home/sobits/catkin_ws/src/sobit_pro/sobit_pro_description/meshes/sensor/lidar_base.stl" scale="0.001 0.001 0.001"/>
      </geometry>
      <material name="black"/>
    </visual>
    <!-- <collision>
      <origin rpy="1.570796326795 0.0 3.14159265359" xyz="0.0 0.0 0.0"/>
      <geometry>
        <mesh filename="/home/sobits/catkin_ws/src/sobit_pro/sobit_pro_description/meshes/sensor/lidar_base.stl" scale="0.001 0.001 0.001"/>
      </geometry>
    </collision> -->
    <inertial>
      <origin rpy="1.570796326795 0.0 3.14159265359" xyz="0.0 0.0 0.0"/>
      <mass value="0.08"/>
      <inertia ixx="1.0" ixy="0.0" ixz="0.0" iyy="1.0" iyz="0.0" izz="1.0"/>
    </inertial>
  </link>


  <joint name="lidar_laser_mount_joint" type="fixed">
    <origin rpy="0.0 0.0 0.0" xyz="0.067 0.0 0.0"/>
    <parent link="lidar_base_link"/>
    <child link="lidar_laser_mount"/>
  </joint>
  <link name="lidar_laser_mount">
    <visual>
      <origin rpy="0 0 0" xyz="0 0 0"/>
      <geometry>
        <!-- Origin of this mesh is the base of the bracket. -->
        <mesh filename="/home/sobits/catkin_ws/src/urg_node/meshes/hokuyo_ust10_20.stl"/>
      </geometry>
      <material name="dark_grey"/>
    </visual>
  </link>


  <joint name="lidar_laser_joint" type="fixed">
    <!-- This offset is from the base of the bracket to the LIDAR's focal point. -->
    <origin rpy="0 0 0" xyz="0 0 0.0474"/>
    <parent link="lidar_laser_mount"/>
    <child link="lidar_laser"/>
  </joint>
  <link name="lidar_laser">
    <inertial>
      <mass value="1.3"/>
      <origin xyz="0 0 0"/>
      <inertia ixx="0.0036300318813199993" ixy="0.0" ixz="0.0" iyy="0.00369730685441" iyz="0.0" izz="0.0023214740714099995"/>
    </inertial>
  </link>


  <joint name="head_camera_joint" type="fixed">
    <parent link="head_camera_tilt_link"/>
    <child link="head_camera_link"/>
    <origin rpy="1.57079632679 0.0 0.0" xyz="-0.0065 0.0 0.0395"/>
  </joint>
  <link name="head_camera_link"/>


  <joint name="head_camera_plug_base_joint" type="fixed">
    <origin rpy="0 0 0" xyz="0.0 0 0.0"/>
    <parent link="head_camera_link"/>
    <child link="head_camera_plug_base_link"/>
  </joint>
  <link name="head_camera_plug_base_link">
    <visual>
      <origin rpy="0.0 0.0 0.0" xyz="0.0 0.0 0.0"/>
      <geometry>
        <mesh filename="/home/sobits/catkin_ws/src/azure_kinect_ros_driver/meshes/akdk_camera.dae"/>
      </geometry>
    </visual>
    <!-- <collision>
      <origin rpy="0.0 0.0 0.0" xyz="0.0 0.0 0.0"/>
      <geometry>
        <mesh filename="/home/sobits/catkin_ws/src/azure_kinect_ros_driver/meshes/akdk_camera.dae"/>
      </geometry>
    </collision> -->
    <inertial>
      <origin rpy="0.0 0.0 0.0" xyz="0.0 0.0 0.0"/>
      <mass value="0.08"/>
      <inertia ixx="1.0" ixy="0.0" ixz="0.0" iyy="1.0" iyz="0.0" izz="1.0"/>
    </inertial>
  </link>


  <joint name="head_camera_visor_base_joint" type="fixed">
    <parent link="head_camera_plug_base_link"/>
    <child link="head_camera_visor_base_link"/>
    <origin rpy="0.0 0.0 0.0" xyz="0.062 0.0 0.005"/>
  </joint>
  <link name="head_camera_visor_base_link"/>


  <joint name="matrix_board_joint" type="fixed">
    <parent link="head_camera_link"/>
    <child link="matrix_board_link"/>
    <origin rpy="0.0 0.0 0.0" xyz="-0.018625 0.0 0.023"/>
  </joint>
  <link name="matrix_board_link"/>


  <joint name="matrix_sensor_0_joint" type="fixed">
    <origin rpy="0.0 0.0 0.0" xyz="0.0 0.0 0.0"/>
    <parent link="matrix_board_link"/>
    <child link="matrix_sensor_0_link"/>
  </joint>
  <link name="matrix_sensor_0_link"/>


  <joint name="matrix_sensor_1_joint" type="fixed">
    <origin rpy="0.0 0.0 0.0" xyz="0.04 0.0 0.0"/>
    <parent link="matrix_board_link"/>
    <child link="matrix_sensor_1_link"/>
  </joint>
  <link name="matrix_sensor_1_link"/>


  <joint name="matrix_sensor_2_joint" type="fixed">
    <origin rpy="0.0 0.0 0.0" xyz="0.02 -0.034541 0.0"/>
    <parent link="matrix_board_link"/>
    <child link="matrix_sensor_2_link"/>
  </joint>
  <link name="matrix_sensor_2_link"/>


  <joint name="matrix_sensor_3_joint" type="fixed">
    <origin rpy="0.0 0.0 0.0" xyz="-0.02 -0.034541 0.0"/>
    <parent link="matrix_board_link"/>
    <child link="matrix_sensor_3_link"/>
  </joint>
  <link name="matrix_sensor_3_link"/>


  <joint name="matrix_sensor_4_joint" type="fixed">
    <origin rpy="0.0 0.0 0.0" xyz="-0.04 0.0 0.0"/>
    <parent link="matrix_board_link"/>
    <child link="matrix_sensor_4_link"/>
  </joint>
  <link name="matrix_sensor_4_link"/>


  <joint name="matrix_sensor_5_joint" type="fixed">
    <origin rpy="0.0 0.0 0.0" xyz="-0.02 0.034541 0.0"/>
    <parent link="matrix_board_link"/>
    <child link="matrix_sensor_5_link"/>
  </joint>
  <link name="matrix_sensor_5_link"/>


  <joint name="matrix_sensor_6_joint" type="fixed">
    <origin rpy="0.0 0.0 0.0" xyz="0.02 0.034541 0.0"/>
    <parent link="matrix_board_link"/>
    <child link="matrix_sensor_6_link"/>
  </joint>
  <link name="matrix_sensor_6_link"/>


  <joint name="hand_camera_base_joint" type="fixed">
    <origin rpy="0.0 0.0 0.0" xyz="0.096519 0.0 -0.024727"/>
    <parent link="arm_wrist_tilt_link"/>
    <child link="hand_camera_base_link"/>
  </joint>
  <link name="hand_camera_base_link"/>
  <!-- camera body, with origin at bottom screw mount -->


  <joint name="hand_camera_joint" type="fixed">
    <origin rpy="0.0 0.0 0.0" xyz="0.0 0.0 0.0"/>
    <parent link="hand_camera_base_link"/>
    <child link="hand_camera_bottom_screw_frame"/>
  </joint>
  <link name="hand_camera_bottom_screw_frame"/>


  <joint name="hand_camera_link_joint" type="fixed">
    <origin rpy="0 0 0" xyz="0.007500000000000001 0.0 0.021150000000000002"/>
    <parent link="hand_camera_bottom_screw_frame"/>
    <child link="hand_camera_link"/>
  </joint>
  <link name="hand_camera_link">
    <visual>
      <origin rpy="1.5707963267948966 0 1.5707963267948966" xyz="-0.0085 0 0.009000000000000001"/>
      <!-- <origin rpy="1.5707963267948966 0 1.5707963267948966" xyz="0.0045 0 0.009000000000000001"/> -->
      <geometry>
        <cylinder length="0.026" radius="0.0305"/>
        <!-- <mesh filename="/home/sobits/catkin_ws/src/realsense_ros/realsense2_description/meshes/l515.dae"/> -->
      </geometry>
    </visual>
    <!-- <collision>
      <origin rpy="1.5707963267948966 0 1.5707963267948966" xyz="-0.0085 0 0.009000000000000001"/>
      <geometry>
        <cylinder length="0.026" radius="0.0305"/>
      </geometry>
    </collision> -->
    <inertial>
      <!-- The following are not reliable values, and should not be used for modeling -->
      <!-- calculated assuming full cylinder as described here: https://en.wikipedia.org/wiki/List_of_moments_of_inertia -->
      <mass value="0.095"/>
      <origin xyz="0 0 0"/>
      <inertia ixx="0.000044" ixy="0.0" ixz="0.0" iyy="0.000027" iyz="0.0" izz="0.000027"/>
    </inertial>
  </link>


  <joint name="hand_camera_lower_mount_joint" type="fixed">
    <origin rpy="0 0 0" xyz="-0.013999999999999999 0 0.01015"/>
    <parent link="hand_camera_bottom_screw_frame"/>
    <child link="hand_camera_lower_mount"/>
  </joint>
  <link name="hand_camera_lower_mount"/>


  <joint name="hand_camera_upper_mount_joint" type="fixed">
    <origin rpy="0 0 0" xyz="-0.013999999999999999 0 0.05015"/>
    <parent link="hand_camera_bottom_screw_frame"/>
    <child link="hand_camera_upper_mount"/>
  </joint>
  <link name="hand_camera_upper_mount"/>
  <!-- camera depth joints and links -->


  <joint name="hand_camera_depth_joint" type="fixed">
    <origin rpy="0 0 0" xyz="0 0 0"/>
    <parent link="hand_camera_link"/>
    <child link="hand_camera_depth_frame"/>
  </joint>
  <link name="hand_camera_depth_frame"/>


  <joint name="hand_camera_depth_optical_joint" type="fixed">
    <origin rpy="-1.5707963267948966 0 -1.5707963267948966" xyz="0 0 0"/>
    <parent link="hand_camera_depth_frame"/>
    <child link="hand_camera_depth_optical_frame"/>
  </joint>
  <link name="hand_camera_depth_optical_frame"/>
  <!-- camera left IR joints and links -->


  <joint name="hand_camera_infra_joint" type="fixed">
    <origin rpy="0 0 0" xyz="0 0.0 0"/>
    <parent link="hand_camera_link"/>
    <child link="hand_camera_infra_frame"/>
  </joint>
  <link name="hand_camera_infra_frame"/>


  <joint name="hand_camera_infra_optical_joint" type="fixed">
    <origin rpy="-1.5707963267948966 0 -1.5707963267948966" xyz="0 0 0"/>
    <parent link="hand_camera_infra_frame"/>
    <child link="hand_camera_infra_optical_frame"/>
  </joint>
  <link name="hand_camera_infra_optical_frame"/>
  <!-- camera color joints and links -->


  <joint name="hand_camera_color_joint" type="fixed">
    <origin rpy="0 0 0" xyz="0 0 0.024"/>
    <parent link="hand_camera_link"/>
    <child link="hand_camera_color_frame"/>
  </joint>
  <link name="hand_camera_color_frame"/>


  <joint name="hand_camera_color_optical_joint" type="fixed">
    <origin rpy="-1.5707963267948966 0 -1.5707963267948966" xyz="0 0 0"/>
    <parent link="hand_camera_color_frame"/>
    <child link="hand_camera_color_optical_frame"/>
  </joint>
  <link name="hand_camera_color_optical_frame"/>
  <!-- camera IMU joints and links -->
  <link name="hand_camera_gyro_frame"/>
  <link name="hand_camera_gyro_optical_frame"/>
  <link name="hand_camera_accel_frame"/>
  <link name="hand_camera_accel_optical_frame"/>


  <joint name="hand_camera_gyro_joint" type="fixed">
    <origin rpy="-0.006161012 0.020193459 0.016301375" xyz="-0.00410137791186571 -0.0129784867167473 0.00256138201802969"/>
    <parent link="hand_camera_color_frame"/>
    <child link="hand_camera_gyro_frame"/>
  </joint>


  <joint name="hand_camera_gyro_optical_joint" type="fixed">
    <origin rpy="-1.5707963267948966 0 -1.5707963267948966" xyz="0 0 0"/>
    <parent link="hand_camera_gyro_frame"/>
    <child link="hand_camera_gyro_optical_frame"/>
  </joint>


  <joint name="hand_camera_accel_joint" type="fixed">
    <origin rpy="-0.006161012 0.020193459 0.016301375" xyz="-0.00410137791186571 -0.0129784867167473 0.00256138201802969"/>
    <parent link="hand_camera_color_frame"/>
    <child link="hand_camera_accel_frame"/>
  </joint>


  <joint name="hand_camera_accel_optical_joint" type="fixed">
    <origin rpy="-1.5707963267948966 0 -1.5707963267948966" xyz="0 0 0"/>
    <parent link="hand_camera_accel_frame"/>
    <child link="hand_camera_accel_optical_frame"/>
  </joint>
</robot>